Workbook

Sheet Raw Data
A1: Order ID | B1: Order Date | C1: Region | D1: Category | E1: Sub-Category | F1: Sales
A2: 1039 | B2: 45646 | C2: West | D2: Furniture | E2: Chairs | F2: 2855.41
A3: 1057 | B3: 45302 | C3: East | D3: Furniture | E3: Bookcases
A4: 1061 | B4: 45473 | C4: South | D4: Clothing | E4: Shoes | F4: 435.75
A5: 1034 | B5: 45343 | C5: North | D5: Furniture | E5: Chairs | F5: 2629.28
A6: 1056 | B6: 45534 | C6: North | D6: Office Supplies | E6: Storage | F6: 1667.44
A7: 1055 | B7: 45594 | C7: South | D7: Office Supplies | E7: Storage | F7: 2488.21
A8: 1054 | B8: 45335 | C8: West | D8: Office Supplies | E8: Binders | F8: 131.27
A9: 1066 | B9: 45389 | C9: North | D9: Furniture | E9: Chairs | F9: 1547.76
A10: 1006 | B10: 45360 | C10: North | D10: Clothing | E10: Shirts | F10: 1645.02
A11: 1049 | B11: 45392 | C11: North | D11: Office Supplies | E11: Paper | F11: 1891
A12: 1000 | B12: 45457 | C12: West | D12: Clothing | E12: Shoes | F12: 192.44
A13: 1016 | B13: 45577 | C13: North | D13: Technology | E13: Copiers | F13: 1083.03
A14: 1044 | B14: 45391 | C14: West | D14: Clothing | E14: Shoes | F14: 2419.81
A15: 1047 | B15: 45601 | C15: North | D15: Clothing | E15: Shoes | F15: 2964.71
... A43: 1035 | B43: 45606 | C43: South | D43: Office Supplies | E43: Storage | F43: 794.16
A44: 1050 | B44: 45604 | C44: East | D44: Clothing | E44: Shoes
A45: 1001 | B45: 45566 | C45: East | D45: Technology | E45: Copiers | F45: 221.1
A46: 1023 | B46: 45546 | C46: East | D46: Office Supplies | E46: Paper | F46: 1234.85
A47: 1005 | B47: 45323 | C47: South | D47: Furniture | E47: Chairs | F47: 187.42
A48: 1020 | B48: 45634 | C48: North | D48: Furniture | E48: Tables | F48: 1098.62
A49: 1022 | B49: 45439 | C49: West | D49: Office Supplies | E49: Paper | F49: 1203.3
A50: 1063 | B50: 45368 | C50: West | D50: Office Supplies | E50: Paper | F50: 1876.35
A51: 1026 | B51: 45382 | C51: West | D51: Office Supplies | E51: Storage | F51: 738.34
A52: 1021 | B52: 45604 | C52: East | D52: Clothing | E52: Shirts | F52: 693.71
A53: 1062 | B53: 45369 | C53: East | D53: Clothing | E53: Shirts | F53: 1845.24
A54: 1067 | B54: 45579 | C54: East | D54: Furniture | E54: Tables | F54: 1010.56
A55: 1030 | B55: 45492 | C55: South | D55: Clothing | E55: Jackets | F55: 355.43
A56: 1045 | B56: 45394 | C56: South | D56: Technology | E56: Copiers | F56: 135.49
... A58: 1014 | B58: 45352 | C58: South | D58: Office Supplies | E58: Paper | F58: 498.35
A59: 1053 | B59: 45462 | C59: East | D59: Clothing | E59: Jackets
A60: 1042 | B60: 45557 | C60: North | D60: Office Supplies | E60: Paper | F60: 2327.22
A61: 1010 | B61: 45510 | C61: North | D61: Clothing | E61: Shoes | F61: 2774.15
A62: 1031 | B62: 45616 | C62: South | D62: Furniture | E62: Chairs | F62: 248.68
A63: 1056 | B63: 45534 | C63: North | D63: Office Supplies | E63: Storage | F63: 1667.44
A64: 1025 | B64: 45504 | C64: North | D64: Clothing | E64: Shirts
A65: 1012 | B65: 45416 | C65: East | D65: Technology | E65: Copiers | F65: 1510.59
A66: 1028 | B66: 45506 | C66: North | D66: Technology | E66: Phones | F66: 2086.96
A67: 1059 | B67: 45400 | C67: North | D67: Office Supplies | E67: Storage | F67: 1011.67
A68: 1017 | B68: 45546 | C68: South | D68: Furniture | E68: Chairs
...

Sheet Cleaned Data
A1: Task 1: Remove duplicates and handle missing values
A2: Missing Sales values are filled with the category average (see Notes).
A4: Order ID | B4: Order Date | C4: Region | D4: Category | E4: Sub-Category | F4: Sales
A5: 1039 | B5: 45646 | C5: West | D5: Furniture | E5: Chairs | F5: 2855.41
A6: 1057 | B6: 45302 | C6: East | D6: Furniture | E6: Bookcases | F6: =IFERROR(AVERAGEIFS('Raw Data'!$F$2:$F$76,'Raw Data'!$D$2:$D$76,D6),0) -> 1424.6021
A7: 1061 | B7: 45473 | C7: South | D7: Clothing | E7: Shoes | F7: 435.75
A8: 1034 | B8: 45343 | C8: North | D8: Furniture | E8: Chairs | F8: 2629.28
A9: 1056 | B9: 45534 | C9: North | D9: Office Supplies | E9: Storage | F9: 1667.44
A10: 1055 | B10: 45594 | C10: South | D10: Office Supplies | E10: Storage | F10: 2488.21
A11: 1054 | B11: 45335 | C11: West | D11: Office Supplies | E11: Binders | F11: 131.27
A12: 1066 | B12: 45389 | C12: North | D12: Furniture | E12: Chairs | F12: 1547.76
A13: 1006 | B13: 45360 | C13: North | D13: Clothing | E13: Shirts | F13: 1645.02
A14: 1049 | B14: 45392 | C14: North | D14: Office Supplies | E14: Paper | F14: 1891
A15: 1000 | B15: 45457 | C15: West | D15: Clothing | E15: Shoes | F15: 192.44
A16: 1016 | B16: 45577 | C16: North | D16: Technology | E16: Copiers | F16: 1083.03
A17: 1044 | B17: 45391 | C17: West | D17: Clothing | E17: Shoes | F17: 2419.81
A18: 1047 | B18: 45601 | C18: North | D18: Clothing | E18: Shoes | F18: 2964.71
... A44: 1035 | B44: 45606 | C44: South | D44: Office Supplies | E44: Storage | F44: 794.16
A45: 1050 | B45: 45604 | C45: East | D45: Clothing | E45: Shoes | F45: =IFERROR(AVERAGEIFS('Raw Data'!$F$2:$F$76,'Raw Data'!$D$2:$D$76,D45),0) -> 1262.5507
A46: 1001 | B46: 45566 | C46: East | D46: Technology | E46: Copiers | F46: 221.1
A47: 1023 | B47: 45546 | C47: East | D47: Office Supplies | E47: Paper | F47: 1234.85
A48: 1005 | B48: 45323 | C48: South | D48: Furniture | E48: Chairs | F48: 187.42
A49: 1020 | B49: 45634 | C49: North | D49: Furniture | E49: Tables | F49: 1098.62
A50: 1022 | B50: 45439 | C50: West | D50: Office Supplies | E50: Paper | F50: 1203.3
A51: 1063 | B51: 45368 | C51: West | D51: Office Supplies | E51: Paper | F51: 1876.35
A52: 1026 | B52: 45382 | C52: West | D52: Office Supplies | E52: Storage | F52: 738.34
A53: 1021 | B53: 45604 | C53: East | D53: Clothing | E53: Shirts | F53: 693.71
A54: 1062 | B54: 45369 | C54: East | D54: Clothing | E54: Shirts | F54: 1845.24
A55: 1067 | B55: 45579 | C55: East | D55: Furniture | E55: Tables | F55: 1010.56
A56: 1045 | B56: 45394 | C56: South | D56: Technology | E56: Copiers | F56: 135.49
A57: 1065 | B57: 45576 | C57: South | D57: Furniture | E57: Bookcases | F57: 217.63
A58: 1014 | B58: 45352 | C58: South | D58: Office Supplies | E58: Paper | F58: 498.35
A59: 1053 | B59: 45462 | C59: East | D59: Clothing | E59: Jackets | F59: =IFERROR(AVERAGEIFS('Raw Data'!$F$2:$F$76,'Raw Data'!$D$2:$D$76,D59),0) -> 1262.5507
A60: 1042 | B60: 45557 | C60: North | D60: Office Supplies | E60: Paper | F60: 2327.22
A61: 1010 | B61: 45510 | C61: North | D61: Clothing | E61: Shoes | F61: 2774.15
A62: 1031 | B62: 45616 | C62: South | D62: Furniture | E62: Chairs | F62: 248.68
A63: 1025 | B63: 45504 | C63: North | D63: Clothing | E63: Shirts | F63: =IFERROR(AVERAGEIFS('Raw Data'!$F$2:$F$76,'Raw Data'!$D$2:$D$76,D63),0) -> 1262.5507
A64: 1012 | B64: 45416 | C64: East | D64: Technology | E64: Copiers | F64: 1510.59
A65: 1028 | B65: 45506 | C65: North | D65: Technology | E65: Phones | F65: 2086.96
A66: 1059 | B66: 45400 | C66: North | D66: Office Supplies | E66: Storage | F66: 1011.67
...

Sheet Pivot - Region Sales
A1: Task 2: Region-wise Sales (Pivot Table summary)
A3: Region | B3: Total Sales | C3: Order Count | D3: Average Sale
A4: East | B4: =SUMIFS('Cleaned Data'!$F$5:$F$74,'Cleaned Data'!$C$5:$C$74,A4) -> 24930.373 | C4: =COUNTIFS('Cleaned Data'!$C$5:$C$74,A4) -> 18 | D4: =IFERROR(B4/C4,0) -> 1385.0207
A5: West | B5: =SUMIFS('Cleaned Data'!$F$5:$F$74,'Cleaned Data'!$C$5:$C$74,A5) -> 18880.46 | C5: =COUNTIFS('Cleaned Data'!$C$5:$C$74,A5) -> 14 | D5: =IFERROR(B5/C5,0) -> 1348.6043
A6: North | B6: =SUMIFS('Cleaned Data'!$F$5:$F$74,'Cleaned Data'!$C$5:$C$74,A6) -> 35519.091 | C6: =COUNTIFS('Cleaned Data'!$C$5:$C$74,A6) -> 20 | D6: =IFERROR(B6/C6,0) -> 1775.9545
A7: South | B7: =SUMIFS('Cleaned Data'!$F$5:$F$74,'Cleaned Data'!$C$5:$C$74,A7) -> 19608.124 | C7: =COUNTIFS('Cleaned Data'!$C$5:$C$74,A7) -> 18 | D7: =IFERROR(B7/C7,0) -> 1089.3402
A8: Grand Total | B8: =SUM(B4:B7) -> 98938.048 | C8: =SUM(C4:C7) -> 70

Sheet Statistics
A1: Task 3: Mean, Median, Mode of Sales (Cleaned Data)
A3: Metric | B3: Formula Used | C3: Value
A4: Mean (Average) | B4: =AVERAGE('Cleaned Data'!$F$5:$F$74) -> 1413.4007 | C4: =AVERAGE('Cleaned Data'!$F$5:$F$74) -> 1413.4007
A5: Median | B5: =MEDIAN('Cleaned Data'!$F$5:$F$74) -> 1376.9261 | C5: =MEDIAN('Cleaned Data'!$F$5:$F$74) -> 1376.9261
A6: Mode | B6: =IFERROR(MODE('Cleaned Data'!$F$5:$F$74),"No mode") -> 1262.5507 | C6: =IFERROR(MODE('Cleaned Data'!$F$5:$F$74),"No mode") -> 1262.5507

Sheet Top 10 Highlighted
A1: Task 4: Conditional formatting - Top 10 Sales highlighted
A3: Order ID | B3: Order Date | C3: Region | D3: Category | E3: Sub-Category | F3: Sales
A4: 1039 | B4: 45646 | C4: West | D4: Furniture | E4: Chairs | F4: ='Cleaned Data'!$F$5 -> 2855.41
A5: 1057 | B5: 45302 | C5: East | D5: Furniture | E5: Bookcases | F5: ='Cleaned Data'!$F$6 -> 1424.6021
A6: 1061 | B6: 45473 | C6: South | D6: Clothing | E6: Shoes | F6: ='Cleaned Data'!$F$7 -> 435.75
A7: 1034 | B7: 45343 | C7: North | D7: Furniture | E7: Chairs | F7: ='Cleaned Data'!$F$8 -> 2629.28
A8: 1056 | B8: 45534 | C8: North | D8: Office Supplies | E8: Storage | F8: ='Cleaned Data'!$F$9 -> 1667.44
A9: 1055 | B9: 45594 | C9: South | D9: Office Supplies | E9: Storage | F9: ='Cleaned Data'!$F$10 -> 2488.21
A10: 1054 | B10: 45335 | C10: West | D10: Office Supplies | E10: Binders | F10: ='Cleaned Data'!$F$11 -> 131.27
A11: 1066 | B11: 45389 | C11: North | D11: Furniture | E11: Chairs | F11: ='Cleaned Data'!$F$12 -> 1547.76
A12: 1006 | B12: 45360 | C12: North | D12: Clothing | E12: Shirts | F12: ='Cleaned Data'!$F$13 -> 1645.02
A13: 1049 | B13: 45392 | C13: North | D13: Office Supplies | E13: Paper | F13: ='Cleaned Data'!$F$14 -> 1891
A14: 1000 | B14: 45457 | C14: West | D14: Clothing | E14: Shoes | F14: ='Cleaned Data'!$F$15 -> 192.44
A15: 1016 | B15: 45577 | C15: North | D15: Technology | E15: Copiers | F15: ='Cleaned Data'!$F$16 -> 1083.03
A16: 1044 | B16: 45391 | C16: West | D16: Clothing | E16: Shoes | F16: ='Cleaned Data'!$F$17 -> 2419.81
A17: 1047 | B17: 45601 | C17: North | D17: Clothing | E17: Shoes | F17: ='Cleaned Data'!$F$18 -> 2964.71
A18: 1011 | B18: 45477 | C18: North | D18: Office Supplies | E18: Binders | F18: ='Cleaned Data'!$F$19 -> 2112.03
A19: 1040 | B19: 45562 | C19: North | D19: Office Supplies | E19: Storage | F19: ='Cleaned Data'!$F$20 -> 1652.36
A20: 1069 | B20: 45536 | C20: West | D20: Technology | E20: Copiers | F20: ='Cleaned Data'!$F$21 -> 2683.63
A21: 1048 | B21: 45478 | C21: East | D21: Office Supplies | E21: Binders | F21: ='Cleaned Data'!$F$22 -> 719.2
A22: 1036 | B22: 45469 | C22: North | D22: Clothing | E22: Shirts | F22: ='Cleaned Data'!$F$23 -> 390.29
A23: 1013 | B23: 45467 | C23: South | D23: Technology | E23: Copiers | F23: ='Cleaned Data'!$F$24 -> 2941.52
A24: 1041 | B24: 45305 | C24: North | D24: Furniture | E24: Bookcases | F24: ='Cleaned Data'!$F$25 -> 2544.07
A25: 1037 | B25: 45541 | C25: South | D25: Clothing | E25: Jackets | F25: ='Cleaned Data'!$F$26 -> 969.96
A26: 1009 | B26: 45324 | C26: East | D26: Office Supplies | E26: Paper | F26: ='Cleaned Data'!$F$27 -> 2057.18
A27: 1030 | B27: 45492 | C27: South | D27: Clothing | E27: Jackets | F27: ='Cleaned Data'!$F$28 -> 355.43
A28: 1008 | B28: 45619 | C28: West | D28: Technology | E28: Phones | F28: ='Cleaned Data'!$F$29 -> 1665.85
A29: 1002 | B29: 45551 | C29: West | D29: Furniture | E29: Chairs | F29: ='Cleaned Data'!$F$30 -> 1329.25
A30: 1003 | B30: 45327 | C30: West | D30: Furniture | E30: Bookcases | F30: ='Cleaned Data'!$F$31 -> 1302.33
A31: 1060 | B31: 45570 | C31: South | D31: Office Supplies | E31: Binders | F31: ='Cleaned Data'!$F$32 -> 2734.55
A32: 1051 | B32: 45621 | C32: East | D32: Furniture | E32: Tables | F32: ='Cleaned Data'!$F$33 -> 2357.79
A33: 1007 | B33: 45584 | C33: North | D33: Office Supplies | E33: Binders | F33: ='Cleaned Data'!$F$34 -> 1765.72
A34: 1004 | B34: 45581 | C34: East | D34: Office Supplies | E34: Storage | F34: ='Cleaned Data'!$F$35 -> 1900.93
A35: 1052 | B35: 45394 | C35: South | D35: Office Supplies | E35: Paper | F35: ='Cleaned Data'!$F$36 -> 2377.95
A36: 1068 | B36: 45550 | C36: West | D36: Technology | E36: Accessories | F36: ='Cleaned Data'!$F$37 -> 1549.06
A37: 1033 | B37: 45318 | C37: East | D37: Furniture | E37: Bookcases | F37: ='Cleaned Data'!$F$38 -> 496.23
A38: 1058 | B38: 45363 | C38: South | D38: Office Supplies | E38: Binders | F38: ='Cleaned Data'!$F$39 -> 132.58
A39: 1024 | B39: 45434 | C39: West | D39: Clothing | E39: Shoes | F39: ='Cleaned Data'!$F$40 -> 871.34
A40: 1043 | B40: 45564 | C40: North | D40: Office Supplies | E40: Storage | F40: ='Cleaned Data'!$F$41 -> 2443.96
A41: 1064 | B41: 45353 | C41: East | D41: Technology | E41: Copiers | F41: ='Cleaned Data'!$F$42 -> 1579.13
...

Sheet Category Revenue Chart
A1: Task 5: Bar chart - Category-wise revenue
A3: Category | B3: Total Revenue
A4: Furniture | B4: =SUMIFS('Cleaned Data'!$F$5:$F$74,'Cleaned Data'!$D$5:$D$74,A4) -> 24218.236
A5: Office Supplies | B5: =SUMIFS('Cleaned Data'!$F$5:$F$74,'Cleaned Data'!$D$5:$D$74,A5) -> 34811.78
A6: Technology | B6: =SUMIFS('Cleaned Data'!$F$5:$F$74,'Cleaned Data'!$D$5:$D$74,A6) -> 17537.55
A7: Clothing | B7: =SUMIFS('Cleaned Data'!$F$5:$F$74,'Cleaned Data'!$D$5:$D$74,A7) -> 22370.482
